<testsuite errors="0" failures="0" tests="11" time="0.01006" timestamp="2010-08-29T21:55:57.941566"><testcase classname="django_hudson.tests.MetaTests" name="test_meta_expected_failure" time="0.00015"><system-out /><system-err /><skipped>Traceback (most recent call last):
  File "/home/lrekucki/projekty/django-hudson/django_hudson/tests/__init__.py", line 20, in test_meta_expected_failure
    self.assertEqual(0, 1, "Broken!")
AssertionError: 0 != 1 : Broken!
</skipped></testcase><testcase classname="django_hudson.tests.MetaTests" name="test_meta_skipping" time="0.00003"><system-out /><system-err /><skipped>This test is skipped!</skipped></testcase><testcase classname="django_hudson.tests.MetaTests" name="test_meta_success" time="0.00003"><system-out /><system-err /></testcase><testcase classname="django_hudson.tests.MetaTests" name="test_meta_unexpected_success" time="0.00005"><system-out /><system-err /><skipped>This test is expected to fail, but it didn't.</skipped></testcase><testcase classname="django_hudson.tests.runners.XMLTestResultTestCase" name="test_error" time="0.00088"><system-out /><system-err /></testcase><testcase classname="django_hudson.tests.runners.XMLTestResultTestCase" name="test_excepted_failure" time="0.00097"><system-out /><system-err /></testcase><testcase classname="django_hudson.tests.runners.XMLTestResultTestCase" name="test_failure" time="0.00070"><system-out /><system-err /></testcase><testcase classname="django_hudson.tests.runners.XMLTestResultTestCase" name="test_no_tests" time="0.00423"><system-out /><system-err /></testcase><testcase classname="django_hudson.tests.runners.XMLTestResultTestCase" name="test_output_buffering" time="0.00080"><system-out /><system-err /></testcase><testcase classname="django_hudson.tests.runners.XMLTestResultTestCase" name="test_skipping" time="0.00061"><system-out /><system-err /></testcase><testcase classname="django_hudson.tests.runners.XMLTestResultTestCase" name="test_success" time="0.00054"><system-out /><system-err /></testcase></testsuite>